Traceback (most recent call last):
  File "/usr/local/lib/python3.10/dist-packages/jupyter_cache/executors/utils.py", line 58, in single_nb_execution
    executenb(
  File "/usr/local/lib/python3.10/dist-packages/nbclient/client.py", line 1305, in execute
    return NotebookClient(nb=nb, resources=resources, km=km, **kwargs).execute()
  File "/usr/local/lib/python3.10/dist-packages/jupyter_core/utils/__init__.py", line 166, in wrapped
    return loop.run_until_complete(inner)
  File "/usr/lib/python3.10/asyncio/base_events.py", line 649, in run_until_complete
    return future.result()
  File "/usr/local/lib/python3.10/dist-packages/nbclient/client.py", line 705, in async_execute
    await self.async_execute_cell(
  File "/usr/local/lib/python3.10/dist-packages/nbclient/client.py", line 1058, in async_execute_cell
    await self._check_raise_for_error(cell, cell_index, exec_reply)
  File "/usr/local/lib/python3.10/dist-packages/nbclient/client.py", line 914, in _check_raise_for_error
    raise CellExecutionError.from_cell_and_msg(cell, exec_reply_content)
nbclient.exceptions.CellExecutionError: An error occurred while executing the following cell:
------------------
import pymysql
import pandas as pd
mydb = pymysql.connect(
  db="petallenght", user="admin",passwd="OjUbSScu",host="mysql-115799-0.cloudclusters.net", port=14338,autocommit=True)
cur = mydb.cursor()
cur.execute("SELECT * FROM iris")
data = cur.fetchall()
column_names = ["id","petallength"]
df_mysql = pd.DataFrame(data, columns=column_names)
print(df_mysql)
------------------


[0;31m[0m
[0;31mgaierror[0mTraceback (most recent call last)
[0;32m/usr/local/lib/python3.10/dist-packages/pymysql/connections.py[0m in [0;36mconnect[0;34m(self, sock)[0m
[1;32m    615[0m                         [0;32mtry[0m[0;34m:[0m[0;34m[0m[0;34m[0m[0m
[0;32m--> 616[0;31m                             sock = socket.create_connection(
[0m[1;32m    617[0m                                 [0;34m([0m[0mself[0m[0;34m.[0m[0mhost[0m[0;34m,[0m [0mself[0m[0;34m.[0m[0mport[0m[0;34m)[0m[0;34m,[0m [0mself[0m[0;34m.[0m[0mconnect_timeout[0m[0;34m,[0m [0;34m**[0m[0mkwargs[0m[0;34m[0m[0;34m[0m[0m

[0;32m/usr/lib/python3.10/socket.py[0m in [0;36mcreate_connection[0;34m(address, timeout, source_address)[0m
[1;32m    823[0m     [0merr[0m [0;34m=[0m [0;32mNone[0m[0;34m[0m[0;34m[0m[0m
[0;32m--> 824[0;31m     [0;32mfor[0m [0mres[0m [0;32min[0m [0mgetaddrinfo[0m[0;34m([0m[0mhost[0m[0;34m,[0m [0mport[0m[0;34m,[0m [0;36m0[0m[0;34m,[0m [0mSOCK_STREAM[0m[0;34m)[0m[0;34m:[0m[0;34m[0m[0;34m[0m[0m
[0m[1;32m    825[0m         [0maf[0m[0;34m,[0m [0msocktype[0m[0;34m,[0m [0mproto[0m[0;34m,[0m [0mcanonname[0m[0;34m,[0m [0msa[0m [0;34m=[0m [0mres[0m[0;34m[0m[0;34m[0m[0m

[0;32m/usr/lib/python3.10/socket.py[0m in [0;36mgetaddrinfo[0;34m(host, port, family, type, proto, flags)[0m
[1;32m    954[0m     [0maddrlist[0m [0;34m=[0m [0;34m[[0m[0;34m][0m[0;34m[0m[0;34m[0m[0m
[0;32m--> 955[0;31m     [0;32mfor[0m [0mres[0m [0;32min[0m [0m_socket[0m[0;34m.[0m[0mgetaddrinfo[0m[0;34m([0m[0mhost[0m[0;34m,[0m [0mport[0m[0;34m,[0m [0mfamily[0m[0;34m,[0m [0mtype[0m[0;34m,[0m [0mproto[0m[0;34m,[0m [0mflags[0m[0;34m)[0m[0;34m:[0m[0;34m[0m[0;34m[0m[0m
[0m[1;32m    956[0m         [0maf[0m[0;34m,[0m [0msocktype[0m[0;34m,[0m [0mproto[0m[0;34m,[0m [0mcanonname[0m[0;34m,[0m [0msa[0m [0;34m=[0m [0mres[0m[0;34m[0m[0;34m[0m[0m

[0;31mgaierror[0m: [Errno -2] Name or service not known

During handling of the above exception, another exception occurred:

[0;31mOperationalError[0mTraceback (most recent call last)
[0;32m<ipython-input-4-c465df568ce3>[0m in [0;36m<cell line: 3>[0;34m()[0m
[1;32m      1[0m [0;32mimport[0m [0mpymysql[0m[0;34m[0m[0;34m[0m[0m
[1;32m      2[0m [0;32mimport[0m [0mpandas[0m [0;32mas[0m [0mpd[0m[0;34m[0m[0;34m[0m[0m
[0;32m----> 3[0;31m mydb = pymysql.connect(
[0m[1;32m      4[0m   db="petallenght", user="admin",passwd="OjUbSScu",host="mysql-115799-0.cloudclusters.net", port=14338,autocommit=True)
[1;32m      5[0m [0mcur[0m [0;34m=[0m [0mmydb[0m[0;34m.[0m[0mcursor[0m[0;34m([0m[0;34m)[0m[0;34m[0m[0;34m[0m[0m

[0;32m/usr/local/lib/python3.10/dist-packages/pymysql/connections.py[0m in [0;36m__init__[0;34m(self, user, password, host, database, unix_socket, port, charset, sql_mode, read_default_file, conv, use_unicode, client_flag, cursorclass, init_command, connect_timeout, read_default_group, autocommit, local_infile, max_allowed_packet, defer_connect, auth_plugin_map, read_timeout, write_timeout, bind_address, binary_prefix, program_name, server_public_key, ssl, ssl_ca, ssl_cert, ssl_disabled, ssl_key, ssl_verify_cert, ssl_verify_identity, compress, named_pipe, passwd, db)[0m
[1;32m    350[0m             [0mself[0m[0;34m.[0m[0m_sock[0m [0;34m=[0m [0;32mNone[0m[0;34m[0m[0;34m[0m[0m
[1;32m    351[0m         [0;32melse[0m[0;34m:[0m[0;34m[0m[0;34m[0m[0m
[0;32m--> 352[0;31m             [0mself[0m[0;34m.[0m[0mconnect[0m[0;34m([0m[0;34m)[0m[0;34m[0m[0;34m[0m[0m
[0m[1;32m    353[0m [0;34m[0m[0m
[1;32m    354[0m     [0;32mdef[0m [0m__enter__[0m[0;34m([0m[0mself[0m[0;34m)[0m[0;34m:[0m[0;34m[0m[0;34m[0m[0m

[0;32m/usr/local/lib/python3.10/dist-packages/pymysql/connections.py[0m in [0;36mconnect[0;34m(self, sock)[0m
[1;32m    666[0m                 [0;32mif[0m [0mDEBUG[0m[0;34m:[0m[0;34m[0m[0;34m[0m[0m
[1;32m    667[0m                     [0mprint[0m[0;34m([0m[0mexc[0m[0;34m.[0m[0mtraceback[0m[0;34m)[0m[0;34m[0m[0;34m[0m[0m
[0;32m--> 668[0;31m                 [0;32mraise[0m [0mexc[0m[0;34m[0m[0;34m[0m[0m
[0m[1;32m    669[0m [0;34m[0m[0m
[1;32m    670[0m             [0;31m# If e is neither DatabaseError or IOError, It's a bug.[0m[0;34m[0m[0;34m[0m[0m

[0;31mOperationalError[0m: (2003, "Can't connect to MySQL server on 'mysql-115799-0.cloudclusters.net' ([Errno -2] Name or service not known)")

